[2024-02-15T13:21:15.327+0000] {taskinstance.py:1159} INFO - Dependencies all met for dep_context=non-requeueable deps ti=<TaskInstance: my_pipeline.load_to_db manual__2024-02-15T13:20:56.498512+00:00 [queued]>
[2024-02-15T13:21:15.332+0000] {taskinstance.py:1159} INFO - Dependencies all met for dep_context=requeueable deps ti=<TaskInstance: my_pipeline.load_to_db manual__2024-02-15T13:20:56.498512+00:00 [queued]>
[2024-02-15T13:21:15.332+0000] {taskinstance.py:1361} INFO - Starting attempt 1 of 1
[2024-02-15T13:21:15.337+0000] {taskinstance.py:1382} INFO - Executing <Task(_PythonDecoratedOperator): load_to_db> on 2024-02-15 13:20:56.498512+00:00
[2024-02-15T13:21:15.341+0000] {standard_task_runner.py:57} INFO - Started process 1674 to run task
[2024-02-15T13:21:15.343+0000] {standard_task_runner.py:84} INFO - Running: ['***', 'tasks', 'run', 'my_pipeline', 'load_to_db', 'manual__2024-02-15T13:20:56.498512+00:00', '--job-id', '21', '--raw', '--subdir', 'DAGS_FOLDER/my_pipeline.py', '--cfg-path', '/tmp/tmpybdgkk3s']
[2024-02-15T13:21:15.345+0000] {standard_task_runner.py:85} INFO - Job 21: Subtask load_to_db
[2024-02-15T13:21:15.373+0000] {task_command.py:415} INFO - Running <TaskInstance: my_pipeline.load_to_db manual__2024-02-15T13:20:56.498512+00:00 [running]> on host c0165191c622
[2024-02-15T13:21:15.566+0000] {taskinstance.py:1660} INFO - Exporting env vars: AIRFLOW_CTX_DAG_OWNER='Admin' AIRFLOW_CTX_DAG_ID='my_pipeline' AIRFLOW_CTX_TASK_ID='load_to_db' AIRFLOW_CTX_EXECUTION_DATE='2024-02-15T13:20:56.498512+00:00' AIRFLOW_CTX_TRY_NUMBER='1' AIRFLOW_CTX_DAG_RUN_ID='manual__2024-02-15T13:20:56.498512+00:00'
[2024-02-15T13:21:15.607+0000] {taskinstance.py:1943} ERROR - Task failed with exception
Traceback (most recent call last):
  File "/home/airflow/.local/lib/python3.8/site-packages/airflow/decorators/base.py", line 221, in execute
    return_value = super().execute(context)
  File "/home/airflow/.local/lib/python3.8/site-packages/airflow/operators/python.py", line 192, in execute
    return_value = self.execute_callable()
  File "/home/airflow/.local/lib/python3.8/site-packages/airflow/operators/python.py", line 209, in execute_callable
    return self.python_callable(*self.op_args, **self.op_kwargs)
  File "/opt/airflow/dags/my_pipeline.py", line 137, in load_to_db
    load_df_to_db(df, table_name)
  File "/opt/airflow/dags/utils/load_df_to_db.py", line 36, in load_df_to_db
    raise e
  File "/opt/airflow/dags/utils/load_df_to_db.py", line 32, in load_df_to_db
    conn.commit()
AttributeError: 'Connection' object has no attribute 'commit'
[2024-02-15T13:21:15.614+0000] {taskinstance.py:1400} INFO - Marking task as FAILED. dag_id=my_pipeline, task_id=load_to_db, execution_date=20240215T132056, start_date=20240215T132115, end_date=20240215T132115
[2024-02-15T13:21:15.620+0000] {standard_task_runner.py:104} ERROR - Failed to execute job 21 for task load_to_db ('Connection' object has no attribute 'commit'; 1674)
[2024-02-15T13:21:15.640+0000] {local_task_job_runner.py:228} INFO - Task exited with return code 1
[2024-02-15T13:21:15.652+0000] {taskinstance.py:2784} INFO - 0 downstream tasks scheduled from follow-on schedule check
