[2024-02-15T13:20:14.906+0000] {taskinstance.py:1159} INFO - Dependencies all met for dep_context=non-requeueable deps ti=<TaskInstance: my_pipeline.load_to_db manual__2024-02-15T13:19:59.215132+00:00 [queued]>
[2024-02-15T13:20:14.910+0000] {taskinstance.py:1159} INFO - Dependencies all met for dep_context=requeueable deps ti=<TaskInstance: my_pipeline.load_to_db manual__2024-02-15T13:19:59.215132+00:00 [queued]>
[2024-02-15T13:20:14.911+0000] {taskinstance.py:1361} INFO - Starting attempt 1 of 1
[2024-02-15T13:20:14.916+0000] {taskinstance.py:1382} INFO - Executing <Task(_PythonDecoratedOperator): load_to_db> on 2024-02-15 13:19:59.215132+00:00
[2024-02-15T13:20:14.919+0000] {standard_task_runner.py:57} INFO - Started process 1643 to run task
[2024-02-15T13:20:14.927+0000] {standard_task_runner.py:84} INFO - Running: ['***', 'tasks', 'run', 'my_pipeline', 'load_to_db', 'manual__2024-02-15T13:19:59.215132+00:00', '--job-id', '19', '--raw', '--subdir', 'DAGS_FOLDER/my_pipeline.py', '--cfg-path', '/tmp/tmp1qoz51jm']
[2024-02-15T13:20:14.935+0000] {standard_task_runner.py:85} INFO - Job 19: Subtask load_to_db
[2024-02-15T13:20:14.971+0000] {task_command.py:415} INFO - Running <TaskInstance: my_pipeline.load_to_db manual__2024-02-15T13:19:59.215132+00:00 [running]> on host c0165191c622
[2024-02-15T13:20:15.288+0000] {taskinstance.py:1660} INFO - Exporting env vars: AIRFLOW_CTX_DAG_OWNER='Admin' AIRFLOW_CTX_DAG_ID='my_pipeline' AIRFLOW_CTX_TASK_ID='load_to_db' AIRFLOW_CTX_EXECUTION_DATE='2024-02-15T13:19:59.215132+00:00' AIRFLOW_CTX_TRY_NUMBER='1' AIRFLOW_CTX_DAG_RUN_ID='manual__2024-02-15T13:19:59.215132+00:00'
[2024-02-15T13:20:15.303+0000] {taskinstance.py:1943} ERROR - Task failed with exception
Traceback (most recent call last):
  File "/home/airflow/.local/lib/python3.8/site-packages/airflow/decorators/base.py", line 221, in execute
    return_value = super().execute(context)
  File "/home/airflow/.local/lib/python3.8/site-packages/airflow/operators/python.py", line 192, in execute
    return_value = self.execute_callable()
  File "/home/airflow/.local/lib/python3.8/site-packages/airflow/operators/python.py", line 209, in execute_callable
    return self.python_callable(*self.op_args, **self.op_kwargs)
  File "/opt/airflow/dags/my_pipeline.py", line 137, in load_to_db
    load_df_to_db(df, table_name)
  File "/opt/airflow/dags/utils/load_df_to_db.py", line 36, in load_df_to_db
    raise e
  File "/opt/airflow/dags/utils/load_df_to_db.py", line 30, in load_df_to_db
    df.to_sql(name=table_name, schema=schema_name, con=conn, if_exists='overwrite', index=False)
  File "/home/airflow/.local/lib/python3.8/site-packages/pandas/core/generic.py", line 2605, in to_sql
    sql.to_sql(
  File "/home/airflow/.local/lib/python3.8/site-packages/pandas/io/sql.py", line 578, in to_sql
    raise ValueError(f"'{if_exists}' is not valid for if_exists")
ValueError: 'overwrite' is not valid for if_exists
[2024-02-15T13:20:15.318+0000] {taskinstance.py:1400} INFO - Marking task as FAILED. dag_id=my_pipeline, task_id=load_to_db, execution_date=20240215T131959, start_date=20240215T132014, end_date=20240215T132015
[2024-02-15T13:20:15.325+0000] {standard_task_runner.py:104} ERROR - Failed to execute job 19 for task load_to_db ('overwrite' is not valid for if_exists; 1643)
[2024-02-15T13:20:15.345+0000] {local_task_job_runner.py:228} INFO - Task exited with return code 1
[2024-02-15T13:20:15.357+0000] {taskinstance.py:2784} INFO - 0 downstream tasks scheduled from follow-on schedule check
